2024-07-04 12:39:08,107 - ERROR - An error occurred: Expecting value: line 1 column 1 (char 0)
Traceback (most recent call last):
  File "/Users/florianrumiel/Documents/GitHub/mcn_load_test/main.py", line 196, in main
    results = await load_tester.run_load_test(prompts, args.connections)
              ^^^^^^^^^^^^^^^^^^^^^^^^^^^^^^^^^^^^^^^^^^^^^^^^^^^^^^^^^^
  File "/Users/florianrumiel/Documents/GitHub/mcn_load_test/core.py", line 135, in run_load_test
    results = await asyncio.gather(*tasks)
              ^^^^^^^^^^^^^^^^^^^^^^^^^^^^
  File "/Users/florianrumiel/Documents/GitHub/mcn_load_test/core.py", line 130, in bounded_send
    prompt, json.loads(result[1])
            ^^^^^^^^^^^^^^^^^^^^^
  File "/opt/homebrew/Cellar/python@3.12/3.12.3/Frameworks/Python.framework/Versions/3.12/lib/python3.12/json/__init__.py", line 346, in loads
    return _default_decoder.decode(s)
           ^^^^^^^^^^^^^^^^^^^^^^^^^^
  File "/opt/homebrew/Cellar/python@3.12/3.12.3/Frameworks/Python.framework/Versions/3.12/lib/python3.12/json/decoder.py", line 337, in decode
    obj, end = self.raw_decode(s, idx=_w(s, 0).end())
               ^^^^^^^^^^^^^^^^^^^^^^^^^^^^^^^^^^^^^^
  File "/opt/homebrew/Cellar/python@3.12/3.12.3/Frameworks/Python.framework/Versions/3.12/lib/python3.12/json/decoder.py", line 355, in raw_decode
    raise JSONDecodeError("Expecting value", s, err.value) from None
json.decoder.JSONDecodeError: Expecting value: line 1 column 1 (char 0)

2024-07-05 15:46:14,811 - ERROR - An error occurred: write_results() takes 2 positional arguments but 4 were given
Traceback (most recent call last):
  File "/Users/florianrumiel/Documents/GitHub/mcn_load_test/main.py", line 225, in main
    write_results(output_filename, stats, results, total_time)
TypeError: write_results() takes 2 positional arguments but 4 were given

