2024-07-04 12:39:08,107 - ERROR - An error occurred: Expecting value: line 1 column 1 (char 0)
Traceback (most recent call last):
  File "/Users/florianrumiel/Documents/GitHub/mcn_load_test/main.py", line 196, in main
    results = await load_tester.run_load_test(prompts, args.connections)
              ^^^^^^^^^^^^^^^^^^^^^^^^^^^^^^^^^^^^^^^^^^^^^^^^^^^^^^^^^^
  File "/Users/florianrumiel/Documents/GitHub/mcn_load_test/core.py", line 135, in run_load_test
    results = await asyncio.gather(*tasks)
              ^^^^^^^^^^^^^^^^^^^^^^^^^^^^
  File "/Users/florianrumiel/Documents/GitHub/mcn_load_test/core.py", line 130, in bounded_send
    prompt, json.loads(result[1])
            ^^^^^^^^^^^^^^^^^^^^^
  File "/opt/homebrew/Cellar/python@3.12/3.12.3/Frameworks/Python.framework/Versions/3.12/lib/python3.12/json/__init__.py", line 346, in loads
    return _default_decoder.decode(s)
           ^^^^^^^^^^^^^^^^^^^^^^^^^^
  File "/opt/homebrew/Cellar/python@3.12/3.12.3/Frameworks/Python.framework/Versions/3.12/lib/python3.12/json/decoder.py", line 337, in decode
    obj, end = self.raw_decode(s, idx=_w(s, 0).end())
               ^^^^^^^^^^^^^^^^^^^^^^^^^^^^^^^^^^^^^^
  File "/opt/homebrew/Cellar/python@3.12/3.12.3/Frameworks/Python.framework/Versions/3.12/lib/python3.12/json/decoder.py", line 355, in raw_decode
    raise JSONDecodeError("Expecting value", s, err.value) from None
json.decoder.JSONDecodeError: Expecting value: line 1 column 1 (char 0)

2024-07-05 15:46:14,811 - ERROR - An error occurred: write_results() takes 2 positional arguments but 4 were given
Traceback (most recent call last):
  File "/Users/florianrumiel/Documents/GitHub/mcn_load_test/main.py", line 225, in main
    write_results(output_filename, stats, results, total_time)
TypeError: write_results() takes 2 positional arguments but 4 were given

2024-07-05 22:53:02,999 - ERROR - status_code: 401, body: {'message': 'No authorization header'}
Traceback (most recent call last):
  File "/Users/florianrumiel/Documents/GitHub/mcn_load_test/venv/lib/python3.12/site-packages/langfuse/client.py", line 363, in auth_check
    projects = self.client.projects.get()
               ^^^^^^^^^^^^^^^^^^^^^^^^^^
  File "/Users/florianrumiel/Documents/GitHub/mcn_load_test/venv/lib/python3.12/site-packages/langfuse/api/resources/projects/client.py", line 82, in get
    raise UnauthorizedError(
langfuse.api.resources.commons.errors.unauthorized_error.UnauthorizedError: status_code: 401, body: {'message': 'No authorization header'}
2024-07-05 22:53:03,210 - ERROR - status_code: 401, body: {'message': 'No authorization header'}
Traceback (most recent call last):
  File "/Users/florianrumiel/Documents/GitHub/mcn_load_test/venv/lib/python3.12/site-packages/langfuse/client.py", line 363, in auth_check
    projects = self.client.projects.get()
               ^^^^^^^^^^^^^^^^^^^^^^^^^^
  File "/Users/florianrumiel/Documents/GitHub/mcn_load_test/venv/lib/python3.12/site-packages/langfuse/api/resources/projects/client.py", line 82, in get
    raise UnauthorizedError(
langfuse.api.resources.commons.errors.unauthorized_error.UnauthorizedError: status_code: 401, body: {'message': 'No authorization header'}
2024-07-05 22:53:03,355 - ERROR - status_code: 401, body: {'message': 'No authorization header'}
Traceback (most recent call last):
  File "/Users/florianrumiel/Documents/GitHub/mcn_load_test/venv/lib/python3.12/site-packages/langfuse/client.py", line 363, in auth_check
    projects = self.client.projects.get()
               ^^^^^^^^^^^^^^^^^^^^^^^^^^
  File "/Users/florianrumiel/Documents/GitHub/mcn_load_test/venv/lib/python3.12/site-packages/langfuse/api/resources/projects/client.py", line 82, in get
    raise UnauthorizedError(
langfuse.api.resources.commons.errors.unauthorized_error.UnauthorizedError: status_code: 401, body: {'message': 'No authorization header'}
2024-07-05 22:53:03,518 - ERROR - status_code: 401, body: {'message': 'No authorization header'}
Traceback (most recent call last):
  File "/Users/florianrumiel/Documents/GitHub/mcn_load_test/venv/lib/python3.12/site-packages/langfuse/client.py", line 363, in auth_check
    projects = self.client.projects.get()
               ^^^^^^^^^^^^^^^^^^^^^^^^^^
  File "/Users/florianrumiel/Documents/GitHub/mcn_load_test/venv/lib/python3.12/site-packages/langfuse/api/resources/projects/client.py", line 82, in get
    raise UnauthorizedError(
langfuse.api.resources.commons.errors.unauthorized_error.UnauthorizedError: status_code: 401, body: {'message': 'No authorization header'}
2024-07-05 22:53:03,743 - ERROR - status_code: 401, body: {'message': 'No authorization header'}
Traceback (most recent call last):
  File "/Users/florianrumiel/Documents/GitHub/mcn_load_test/venv/lib/python3.12/site-packages/langfuse/client.py", line 363, in auth_check
    projects = self.client.projects.get()
               ^^^^^^^^^^^^^^^^^^^^^^^^^^
  File "/Users/florianrumiel/Documents/GitHub/mcn_load_test/venv/lib/python3.12/site-packages/langfuse/api/resources/projects/client.py", line 82, in get
    raise UnauthorizedError(
langfuse.api.resources.commons.errors.unauthorized_error.UnauthorizedError: status_code: 401, body: {'message': 'No authorization header'}
2024-07-05 22:53:07,307 - ERROR - status_code: 401, body: {'message': 'No authorization header'}
Traceback (most recent call last):
  File "/Users/florianrumiel/Documents/GitHub/mcn_load_test/venv/lib/python3.12/site-packages/langfuse/client.py", line 363, in auth_check
    projects = self.client.projects.get()
               ^^^^^^^^^^^^^^^^^^^^^^^^^^
  File "/Users/florianrumiel/Documents/GitHub/mcn_load_test/venv/lib/python3.12/site-packages/langfuse/api/resources/projects/client.py", line 82, in get
    raise UnauthorizedError(
langfuse.api.resources.commons.errors.unauthorized_error.UnauthorizedError: status_code: 401, body: {'message': 'No authorization header'}
2024-07-05 22:53:08,181 - ERROR - status_code: 401, body: {'message': 'No authorization header'}
Traceback (most recent call last):
  File "/Users/florianrumiel/Documents/GitHub/mcn_load_test/venv/lib/python3.12/site-packages/langfuse/client.py", line 363, in auth_check
    projects = self.client.projects.get()
               ^^^^^^^^^^^^^^^^^^^^^^^^^^
  File "/Users/florianrumiel/Documents/GitHub/mcn_load_test/venv/lib/python3.12/site-packages/langfuse/api/resources/projects/client.py", line 82, in get
    raise UnauthorizedError(
langfuse.api.resources.commons.errors.unauthorized_error.UnauthorizedError: status_code: 401, body: {'message': 'No authorization header'}
2024-07-05 22:53:09,727 - ERROR - status_code: 401, body: {'message': 'No authorization header'}
Traceback (most recent call last):
  File "/Users/florianrumiel/Documents/GitHub/mcn_load_test/venv/lib/python3.12/site-packages/langfuse/client.py", line 363, in auth_check
    projects = self.client.projects.get()
               ^^^^^^^^^^^^^^^^^^^^^^^^^^
  File "/Users/florianrumiel/Documents/GitHub/mcn_load_test/venv/lib/python3.12/site-packages/langfuse/api/resources/projects/client.py", line 82, in get
    raise UnauthorizedError(
langfuse.api.resources.commons.errors.unauthorized_error.UnauthorizedError: status_code: 401, body: {'message': 'No authorization header'}
2024-07-05 22:53:09,868 - ERROR - status_code: 401, body: {'message': 'No authorization header'}
Traceback (most recent call last):
  File "/Users/florianrumiel/Documents/GitHub/mcn_load_test/venv/lib/python3.12/site-packages/langfuse/client.py", line 363, in auth_check
    projects = self.client.projects.get()
               ^^^^^^^^^^^^^^^^^^^^^^^^^^
  File "/Users/florianrumiel/Documents/GitHub/mcn_load_test/venv/lib/python3.12/site-packages/langfuse/api/resources/projects/client.py", line 82, in get
    raise UnauthorizedError(
langfuse.api.resources.commons.errors.unauthorized_error.UnauthorizedError: status_code: 401, body: {'message': 'No authorization header'}
2024-07-05 22:53:10,012 - ERROR - status_code: 401, body: {'message': 'No authorization header'}
Traceback (most recent call last):
  File "/Users/florianrumiel/Documents/GitHub/mcn_load_test/venv/lib/python3.12/site-packages/langfuse/client.py", line 363, in auth_check
    projects = self.client.projects.get()
               ^^^^^^^^^^^^^^^^^^^^^^^^^^
  File "/Users/florianrumiel/Documents/GitHub/mcn_load_test/venv/lib/python3.12/site-packages/langfuse/api/resources/projects/client.py", line 82, in get
    raise UnauthorizedError(
langfuse.api.resources.commons.errors.unauthorized_error.UnauthorizedError: status_code: 401, body: {'message': 'No authorization header'}
2024-07-05 22:53:10,158 - ERROR - status_code: 401, body: {'message': 'No authorization header'}
Traceback (most recent call last):
  File "/Users/florianrumiel/Documents/GitHub/mcn_load_test/venv/lib/python3.12/site-packages/langfuse/client.py", line 363, in auth_check
    projects = self.client.projects.get()
               ^^^^^^^^^^^^^^^^^^^^^^^^^^
  File "/Users/florianrumiel/Documents/GitHub/mcn_load_test/venv/lib/python3.12/site-packages/langfuse/api/resources/projects/client.py", line 82, in get
    raise UnauthorizedError(
langfuse.api.resources.commons.errors.unauthorized_error.UnauthorizedError: status_code: 401, body: {'message': 'No authorization header'}
2024-07-05 22:53:11,254 - ERROR - status_code: 401, body: {'message': 'No authorization header'}
Traceback (most recent call last):
  File "/Users/florianrumiel/Documents/GitHub/mcn_load_test/venv/lib/python3.12/site-packages/langfuse/client.py", line 363, in auth_check
    projects = self.client.projects.get()
               ^^^^^^^^^^^^^^^^^^^^^^^^^^
  File "/Users/florianrumiel/Documents/GitHub/mcn_load_test/venv/lib/python3.12/site-packages/langfuse/api/resources/projects/client.py", line 82, in get
    raise UnauthorizedError(
langfuse.api.resources.commons.errors.unauthorized_error.UnauthorizedError: status_code: 401, body: {'message': 'No authorization header'}
2024-07-05 22:53:13,457 - ERROR - status_code: 401, body: {'message': 'No authorization header'}
Traceback (most recent call last):
  File "/Users/florianrumiel/Documents/GitHub/mcn_load_test/venv/lib/python3.12/site-packages/langfuse/client.py", line 363, in auth_check
    projects = self.client.projects.get()
               ^^^^^^^^^^^^^^^^^^^^^^^^^^
  File "/Users/florianrumiel/Documents/GitHub/mcn_load_test/venv/lib/python3.12/site-packages/langfuse/api/resources/projects/client.py", line 82, in get
    raise UnauthorizedError(
langfuse.api.resources.commons.errors.unauthorized_error.UnauthorizedError: status_code: 401, body: {'message': 'No authorization header'}
2024-07-05 22:53:14,276 - ERROR - status_code: 401, body: {'message': 'No authorization header'}
Traceback (most recent call last):
  File "/Users/florianrumiel/Documents/GitHub/mcn_load_test/venv/lib/python3.12/site-packages/langfuse/client.py", line 363, in auth_check
    projects = self.client.projects.get()
               ^^^^^^^^^^^^^^^^^^^^^^^^^^
  File "/Users/florianrumiel/Documents/GitHub/mcn_load_test/venv/lib/python3.12/site-packages/langfuse/api/resources/projects/client.py", line 82, in get
    raise UnauthorizedError(
langfuse.api.resources.commons.errors.unauthorized_error.UnauthorizedError: status_code: 401, body: {'message': 'No authorization header'}
2024-07-05 22:53:16,410 - ERROR - status_code: 401, body: {'message': 'No authorization header'}
Traceback (most recent call last):
  File "/Users/florianrumiel/Documents/GitHub/mcn_load_test/venv/lib/python3.12/site-packages/langfuse/client.py", line 363, in auth_check
    projects = self.client.projects.get()
               ^^^^^^^^^^^^^^^^^^^^^^^^^^
  File "/Users/florianrumiel/Documents/GitHub/mcn_load_test/venv/lib/python3.12/site-packages/langfuse/api/resources/projects/client.py", line 82, in get
    raise UnauthorizedError(
langfuse.api.resources.commons.errors.unauthorized_error.UnauthorizedError: status_code: 401, body: {'message': 'No authorization header'}
2024-07-05 22:56:03,652 - ERROR - status_code: 404, body: {'message': 'Dataset not found', 'error': 'LangfuseNotFoundError'}
Traceback (most recent call last):
  File "/Users/florianrumiel/Documents/GitHub/mcn_load_test/venv/lib/python3.12/site-packages/langfuse/client.py", line 509, in create_dataset_item
    return self.client.dataset_items.create(request=body)
           ^^^^^^^^^^^^^^^^^^^^^^^^^^^^^^^^^^^^^^^^^^^^^^
  File "/Users/florianrumiel/Documents/GitHub/mcn_load_test/venv/lib/python3.12/site-packages/langfuse/api/resources/dataset_items/client.py", line 129, in create
    raise NotFoundError(pydantic_v1.parse_obj_as(typing.Any, _response.json()))  # type: ignore
    ^^^^^^^^^^^^^^^^^^^^^^^^^^^^^^^^^^^^^^^^^^^^^^^^^^^^^^^^^^^^^^^^^^^^^^^^^^^
langfuse.api.resources.commons.errors.not_found_error.NotFoundError: status_code: 404, body: {'message': 'Dataset not found', 'error': 'LangfuseNotFoundError'}
2024-07-05 22:56:04,171 - ERROR - status_code: 404, body: {'message': 'Dataset not found', 'error': 'LangfuseNotFoundError'}
Traceback (most recent call last):
  File "/Users/florianrumiel/Documents/GitHub/mcn_load_test/venv/lib/python3.12/site-packages/langfuse/client.py", line 509, in create_dataset_item
    return self.client.dataset_items.create(request=body)
           ^^^^^^^^^^^^^^^^^^^^^^^^^^^^^^^^^^^^^^^^^^^^^^
  File "/Users/florianrumiel/Documents/GitHub/mcn_load_test/venv/lib/python3.12/site-packages/langfuse/api/resources/dataset_items/client.py", line 129, in create
    raise NotFoundError(pydantic_v1.parse_obj_as(typing.Any, _response.json()))  # type: ignore
    ^^^^^^^^^^^^^^^^^^^^^^^^^^^^^^^^^^^^^^^^^^^^^^^^^^^^^^^^^^^^^^^^^^^^^^^^^^^
langfuse.api.resources.commons.errors.not_found_error.NotFoundError: status_code: 404, body: {'message': 'Dataset not found', 'error': 'LangfuseNotFoundError'}
2024-07-05 22:56:04,877 - ERROR - status_code: 404, body: {'message': 'Dataset not found', 'error': 'LangfuseNotFoundError'}
Traceback (most recent call last):
  File "/Users/florianrumiel/Documents/GitHub/mcn_load_test/venv/lib/python3.12/site-packages/langfuse/client.py", line 509, in create_dataset_item
    return self.client.dataset_items.create(request=body)
           ^^^^^^^^^^^^^^^^^^^^^^^^^^^^^^^^^^^^^^^^^^^^^^
  File "/Users/florianrumiel/Documents/GitHub/mcn_load_test/venv/lib/python3.12/site-packages/langfuse/api/resources/dataset_items/client.py", line 129, in create
    raise NotFoundError(pydantic_v1.parse_obj_as(typing.Any, _response.json()))  # type: ignore
    ^^^^^^^^^^^^^^^^^^^^^^^^^^^^^^^^^^^^^^^^^^^^^^^^^^^^^^^^^^^^^^^^^^^^^^^^^^^
langfuse.api.resources.commons.errors.not_found_error.NotFoundError: status_code: 404, body: {'message': 'Dataset not found', 'error': 'LangfuseNotFoundError'}
2024-07-05 22:56:05,231 - ERROR - status_code: 404, body: {'message': 'Dataset not found', 'error': 'LangfuseNotFoundError'}
Traceback (most recent call last):
  File "/Users/florianrumiel/Documents/GitHub/mcn_load_test/venv/lib/python3.12/site-packages/langfuse/client.py", line 509, in create_dataset_item
    return self.client.dataset_items.create(request=body)
           ^^^^^^^^^^^^^^^^^^^^^^^^^^^^^^^^^^^^^^^^^^^^^^
  File "/Users/florianrumiel/Documents/GitHub/mcn_load_test/venv/lib/python3.12/site-packages/langfuse/api/resources/dataset_items/client.py", line 129, in create
    raise NotFoundError(pydantic_v1.parse_obj_as(typing.Any, _response.json()))  # type: ignore
    ^^^^^^^^^^^^^^^^^^^^^^^^^^^^^^^^^^^^^^^^^^^^^^^^^^^^^^^^^^^^^^^^^^^^^^^^^^^
langfuse.api.resources.commons.errors.not_found_error.NotFoundError: status_code: 404, body: {'message': 'Dataset not found', 'error': 'LangfuseNotFoundError'}
2024-07-05 22:56:05,237 - ERROR - An error occurred: Expecting value: line 1 column 1 (char 0)
Traceback (most recent call last):
  File "/Users/florianrumiel/Documents/GitHub/mcn_load_test/main.py", line 215, in main
    results = await load_tester.run_load_test(prompts, args.connections)
              ^^^^^^^^^^^^^^^^^^^^^^^^^^^^^^^^^^^^^^^^^^^^^^^^^^^^^^^^^^
  File "/Users/florianrumiel/Documents/GitHub/mcn_load_test/core.py", line 167, in run_load_test
    results = await asyncio.gather(*tasks)
              ^^^^^^^^^^^^^^^^^^^^^^^^^^^^
  File "/Users/florianrumiel/Documents/GitHub/mcn_load_test/core.py", line 162, in bounded_send
    prompt, json.loads(result[1])
            ^^^^^^^^^^^^^^^^^^^^^
  File "/opt/homebrew/Cellar/python@3.12/3.12.3/Frameworks/Python.framework/Versions/3.12/lib/python3.12/json/__init__.py", line 346, in loads
    return _default_decoder.decode(s)
           ^^^^^^^^^^^^^^^^^^^^^^^^^^
  File "/opt/homebrew/Cellar/python@3.12/3.12.3/Frameworks/Python.framework/Versions/3.12/lib/python3.12/json/decoder.py", line 337, in decode
    obj, end = self.raw_decode(s, idx=_w(s, 0).end())
               ^^^^^^^^^^^^^^^^^^^^^^^^^^^^^^^^^^^^^^
  File "/opt/homebrew/Cellar/python@3.12/3.12.3/Frameworks/Python.framework/Versions/3.12/lib/python3.12/json/decoder.py", line 355, in raw_decode
    raise JSONDecodeError("Expecting value", s, err.value) from None
json.decoder.JSONDecodeError: Expecting value: line 1 column 1 (char 0)

2024-07-05 22:56:05,308 - ERROR - unhandled exception during asyncio.run() shutdown
task: <Task finished name='Task-13' coro=<WebSocketLoadTester.run_load_test.<locals>.bounded_send() done, defined at /Users/florianrumiel/Documents/GitHub/mcn_load_test/core.py:156> exception=JSONDecodeError('Expecting value: line 1 column 1 (char 0)')>
Traceback (most recent call last):
  File "/Users/florianrumiel/Documents/GitHub/mcn_load_test/core.py", line 162, in bounded_send
    prompt, json.loads(result[1])
            ^^^^^^^^^^^^^^^^^^^^^
  File "/opt/homebrew/Cellar/python@3.12/3.12.3/Frameworks/Python.framework/Versions/3.12/lib/python3.12/json/__init__.py", line 346, in loads
    return _default_decoder.decode(s)
           ^^^^^^^^^^^^^^^^^^^^^^^^^^
  File "/opt/homebrew/Cellar/python@3.12/3.12.3/Frameworks/Python.framework/Versions/3.12/lib/python3.12/json/decoder.py", line 337, in decode
    obj, end = self.raw_decode(s, idx=_w(s, 0).end())
               ^^^^^^^^^^^^^^^^^^^^^^^^^^^^^^^^^^^^^^
  File "/opt/homebrew/Cellar/python@3.12/3.12.3/Frameworks/Python.framework/Versions/3.12/lib/python3.12/json/decoder.py", line 355, in raw_decode
    raise JSONDecodeError("Expecting value", s, err.value) from None
json.decoder.JSONDecodeError: Expecting value: line 1 column 1 (char 0)
2024-07-05 23:00:51,931 - ERROR - status_code: 404, body: {'message': 'Dataset not found', 'error': 'LangfuseNotFoundError'}
Traceback (most recent call last):
  File "/Users/florianrumiel/Documents/GitHub/mcn_load_test/venv/lib/python3.12/site-packages/langfuse/client.py", line 509, in create_dataset_item
    return self.client.dataset_items.create(request=body)
           ^^^^^^^^^^^^^^^^^^^^^^^^^^^^^^^^^^^^^^^^^^^^^^
  File "/Users/florianrumiel/Documents/GitHub/mcn_load_test/venv/lib/python3.12/site-packages/langfuse/api/resources/dataset_items/client.py", line 129, in create
    raise NotFoundError(pydantic_v1.parse_obj_as(typing.Any, _response.json()))  # type: ignore
    ^^^^^^^^^^^^^^^^^^^^^^^^^^^^^^^^^^^^^^^^^^^^^^^^^^^^^^^^^^^^^^^^^^^^^^^^^^^
langfuse.api.resources.commons.errors.not_found_error.NotFoundError: status_code: 404, body: {'message': 'Dataset not found', 'error': 'LangfuseNotFoundError'}
2024-07-05 23:00:52,290 - ERROR - status_code: 404, body: {'message': 'Dataset not found', 'error': 'LangfuseNotFoundError'}
Traceback (most recent call last):
  File "/Users/florianrumiel/Documents/GitHub/mcn_load_test/venv/lib/python3.12/site-packages/langfuse/client.py", line 509, in create_dataset_item
    return self.client.dataset_items.create(request=body)
           ^^^^^^^^^^^^^^^^^^^^^^^^^^^^^^^^^^^^^^^^^^^^^^
  File "/Users/florianrumiel/Documents/GitHub/mcn_load_test/venv/lib/python3.12/site-packages/langfuse/api/resources/dataset_items/client.py", line 129, in create
    raise NotFoundError(pydantic_v1.parse_obj_as(typing.Any, _response.json()))  # type: ignore
    ^^^^^^^^^^^^^^^^^^^^^^^^^^^^^^^^^^^^^^^^^^^^^^^^^^^^^^^^^^^^^^^^^^^^^^^^^^^
langfuse.api.resources.commons.errors.not_found_error.NotFoundError: status_code: 404, body: {'message': 'Dataset not found', 'error': 'LangfuseNotFoundError'}
2024-07-05 23:00:52,297 - ERROR - An error occurred: Expecting value: line 1 column 1 (char 0)
Traceback (most recent call last):
  File "/Users/florianrumiel/Documents/GitHub/mcn_load_test/main.py", line 215, in main
    results = await load_tester.run_load_test(prompts, args.connections)
              ^^^^^^^^^^^^^^^^^^^^^^^^^^^^^^^^^^^^^^^^^^^^^^^^^^^^^^^^^^
  File "/Users/florianrumiel/Documents/GitHub/mcn_load_test/core.py", line 167, in run_load_test
    results = await asyncio.gather(*tasks)
              ^^^^^^^^^^^^^^^^^^^^^^^^^^^^
  File "/Users/florianrumiel/Documents/GitHub/mcn_load_test/core.py", line 162, in bounded_send
    prompt, json.loads(result[1])
            ^^^^^^^^^^^^^^^^^^^^^
  File "/opt/homebrew/Cellar/python@3.12/3.12.3/Frameworks/Python.framework/Versions/3.12/lib/python3.12/json/__init__.py", line 346, in loads
    return _default_decoder.decode(s)
           ^^^^^^^^^^^^^^^^^^^^^^^^^^
  File "/opt/homebrew/Cellar/python@3.12/3.12.3/Frameworks/Python.framework/Versions/3.12/lib/python3.12/json/decoder.py", line 337, in decode
    obj, end = self.raw_decode(s, idx=_w(s, 0).end())
               ^^^^^^^^^^^^^^^^^^^^^^^^^^^^^^^^^^^^^^
  File "/opt/homebrew/Cellar/python@3.12/3.12.3/Frameworks/Python.framework/Versions/3.12/lib/python3.12/json/decoder.py", line 355, in raw_decode
    raise JSONDecodeError("Expecting value", s, err.value) from None
json.decoder.JSONDecodeError: Expecting value: line 1 column 1 (char 0)

2024-07-05 23:00:52,392 - ERROR - unhandled exception during asyncio.run() shutdown
task: <Task finished name='Task-15' coro=<WebSocketLoadTester.run_load_test.<locals>.bounded_send() done, defined at /Users/florianrumiel/Documents/GitHub/mcn_load_test/core.py:156> exception=JSONDecodeError('Expecting value: line 1 column 1 (char 0)')>
Traceback (most recent call last):
  File "/Users/florianrumiel/Documents/GitHub/mcn_load_test/core.py", line 162, in bounded_send
    prompt, json.loads(result[1])
            ^^^^^^^^^^^^^^^^^^^^^
  File "/opt/homebrew/Cellar/python@3.12/3.12.3/Frameworks/Python.framework/Versions/3.12/lib/python3.12/json/__init__.py", line 346, in loads
    return _default_decoder.decode(s)
           ^^^^^^^^^^^^^^^^^^^^^^^^^^
  File "/opt/homebrew/Cellar/python@3.12/3.12.3/Frameworks/Python.framework/Versions/3.12/lib/python3.12/json/decoder.py", line 337, in decode
    obj, end = self.raw_decode(s, idx=_w(s, 0).end())
               ^^^^^^^^^^^^^^^^^^^^^^^^^^^^^^^^^^^^^^
  File "/opt/homebrew/Cellar/python@3.12/3.12.3/Frameworks/Python.framework/Versions/3.12/lib/python3.12/json/decoder.py", line 355, in raw_decode
    raise JSONDecodeError("Expecting value", s, err.value) from None
json.decoder.JSONDecodeError: Expecting value: line 1 column 1 (char 0)
2024-07-05 23:05:18,099 - ERROR - An error occurred: Expecting value: line 1 column 1 (char 0)
Traceback (most recent call last):
  File "/Users/florianrumiel/Documents/GitHub/mcn_load_test/main.py", line 215, in main
    results = await load_tester.run_load_test(prompts, args.connections)
              ^^^^^^^^^^^^^^^^^^^^^^^^^^^^^^^^^^^^^^^^^^^^^^^^^^^^^^^^^^
  File "/Users/florianrumiel/Documents/GitHub/mcn_load_test/core.py", line 178, in run_load_test
    results = await asyncio.gather(*tasks)
              ^^^^^^^^^^^^^^^^^^^^^^^^^^^^
  File "/Users/florianrumiel/Documents/GitHub/mcn_load_test/core.py", line 173, in bounded_send
    prompt, json.loads(result[1])
            ^^^^^^^^^^^^^^^^^^^^^
  File "/opt/homebrew/Cellar/python@3.12/3.12.3/Frameworks/Python.framework/Versions/3.12/lib/python3.12/json/__init__.py", line 346, in loads
    return _default_decoder.decode(s)
           ^^^^^^^^^^^^^^^^^^^^^^^^^^
  File "/opt/homebrew/Cellar/python@3.12/3.12.3/Frameworks/Python.framework/Versions/3.12/lib/python3.12/json/decoder.py", line 337, in decode
    obj, end = self.raw_decode(s, idx=_w(s, 0).end())
               ^^^^^^^^^^^^^^^^^^^^^^^^^^^^^^^^^^^^^^
  File "/opt/homebrew/Cellar/python@3.12/3.12.3/Frameworks/Python.framework/Versions/3.12/lib/python3.12/json/decoder.py", line 355, in raw_decode
    raise JSONDecodeError("Expecting value", s, err.value) from None
json.decoder.JSONDecodeError: Expecting value: line 1 column 1 (char 0)

2024-07-05 23:05:18,168 - ERROR - unhandled exception during asyncio.run() shutdown
task: <Task finished name='Task-7' coro=<WebSocketLoadTester.run_load_test.<locals>.bounded_send() done, defined at /Users/florianrumiel/Documents/GitHub/mcn_load_test/core.py:167> exception=JSONDecodeError('Expecting value: line 1 column 1 (char 0)')>
Traceback (most recent call last):
  File "/Users/florianrumiel/Documents/GitHub/mcn_load_test/core.py", line 173, in bounded_send
    prompt, json.loads(result[1])
            ^^^^^^^^^^^^^^^^^^^^^
  File "/opt/homebrew/Cellar/python@3.12/3.12.3/Frameworks/Python.framework/Versions/3.12/lib/python3.12/json/__init__.py", line 346, in loads
    return _default_decoder.decode(s)
           ^^^^^^^^^^^^^^^^^^^^^^^^^^
  File "/opt/homebrew/Cellar/python@3.12/3.12.3/Frameworks/Python.framework/Versions/3.12/lib/python3.12/json/decoder.py", line 337, in decode
    obj, end = self.raw_decode(s, idx=_w(s, 0).end())
               ^^^^^^^^^^^^^^^^^^^^^^^^^^^^^^^^^^^^^^
  File "/opt/homebrew/Cellar/python@3.12/3.12.3/Frameworks/Python.framework/Versions/3.12/lib/python3.12/json/decoder.py", line 355, in raw_decode
    raise JSONDecodeError("Expecting value", s, err.value) from None
json.decoder.JSONDecodeError: Expecting value: line 1 column 1 (char 0)
2024-07-05 23:08:16,074 - ERROR - An error occurred: Expecting value: line 1 column 1 (char 0)
Traceback (most recent call last):
  File "/Users/florianrumiel/Documents/GitHub/mcn_load_test/main.py", line 215, in main
    results = await load_tester.run_load_test(prompts, args.connections)
              ^^^^^^^^^^^^^^^^^^^^^^^^^^^^^^^^^^^^^^^^^^^^^^^^^^^^^^^^^^
  File "/Users/florianrumiel/Documents/GitHub/mcn_load_test/core.py", line 178, in run_load_test
    results = await asyncio.gather(*tasks)
              ^^^^^^^^^^^^^^^^^^^^^^^^^^^^
  File "/Users/florianrumiel/Documents/GitHub/mcn_load_test/core.py", line 173, in bounded_send
    prompt, json.loads(result[1])
            ^^^^^^^^^^^^^^^^^^^^^
  File "/opt/homebrew/Cellar/python@3.12/3.12.3/Frameworks/Python.framework/Versions/3.12/lib/python3.12/json/__init__.py", line 346, in loads
    return _default_decoder.decode(s)
           ^^^^^^^^^^^^^^^^^^^^^^^^^^
  File "/opt/homebrew/Cellar/python@3.12/3.12.3/Frameworks/Python.framework/Versions/3.12/lib/python3.12/json/decoder.py", line 337, in decode
    obj, end = self.raw_decode(s, idx=_w(s, 0).end())
               ^^^^^^^^^^^^^^^^^^^^^^^^^^^^^^^^^^^^^^
  File "/opt/homebrew/Cellar/python@3.12/3.12.3/Frameworks/Python.framework/Versions/3.12/lib/python3.12/json/decoder.py", line 355, in raw_decode
    raise JSONDecodeError("Expecting value", s, err.value) from None
json.decoder.JSONDecodeError: Expecting value: line 1 column 1 (char 0)

